[2023-12-01T15:38:13.921+0000] {taskinstance.py:1159} INFO - Dependencies all met for dep_context=non-requeueable deps ti=<TaskInstance: zillow_analytics_dag.tsk_transfer_s3_to_redshift manual__2023-12-01T15:29:37.526614+00:00 [queued]>
[2023-12-01T15:38:13.929+0000] {taskinstance.py:1159} INFO - Dependencies all met for dep_context=requeueable deps ti=<TaskInstance: zillow_analytics_dag.tsk_transfer_s3_to_redshift manual__2023-12-01T15:29:37.526614+00:00 [queued]>
[2023-12-01T15:38:13.930+0000] {taskinstance.py:1361} INFO - Starting attempt 2 of 3
[2023-12-01T15:38:13.945+0000] {taskinstance.py:1382} INFO - Executing <Task(S3ToRedshiftOperator): tsk_transfer_s3_to_redshift> on 2023-12-01 15:29:37.526614+00:00
[2023-12-01T15:38:13.949+0000] {standard_task_runner.py:57} INFO - Started process 37166 to run task
[2023-12-01T15:38:13.953+0000] {standard_task_runner.py:84} INFO - Running: ['airflow', 'tasks', 'run', 'zillow_analytics_dag', 'tsk_transfer_s3_to_redshift', 'manual__2023-12-01T15:29:37.526614+00:00', '--job-id', '80', '--raw', '--subdir', '/home/ubuntu/airflow/dags', '--cfg-path', '/tmp/tmpxnzy71vi']
[2023-12-01T15:38:13.955+0000] {standard_task_runner.py:85} INFO - Job 80: Subtask tsk_transfer_s3_to_redshift
[2023-12-01T15:38:13.992+0000] {task_command.py:416} INFO - Running <TaskInstance: zillow_analytics_dag.tsk_transfer_s3_to_redshift manual__2023-12-01T15:29:37.526614+00:00 [running]> on host ip-172-31-24-255.us-west-2.compute.internal
[2023-12-01T15:38:14.063+0000] {taskinstance.py:1662} INFO - Exporting env vars: AIRFLOW_CTX_DAG_EMAIL='myemail@domain.com' AIRFLOW_CTX_DAG_OWNER='airflow' AIRFLOW_CTX_DAG_ID='zillow_analytics_dag' AIRFLOW_CTX_TASK_ID='tsk_transfer_s3_to_redshift' AIRFLOW_CTX_EXECUTION_DATE='2023-12-01T15:29:37.526614+00:00' AIRFLOW_CTX_TRY_NUMBER='2' AIRFLOW_CTX_DAG_RUN_ID='manual__2023-12-01T15:29:37.526614+00:00'
[2023-12-01T15:38:14.068+0000] {base.py:73} INFO - Using connection ID 'aws_s3_conn' for task execution.
[2023-12-01T15:38:14.071+0000] {base.py:73} INFO - Using connection ID 'aws_s3_conn' for task execution.
[2023-12-01T15:38:14.071+0000] {connection_wrapper.py:378} INFO - AWS Connection (conn_id='aws_s3_conn', conn_type='aws') credentials retrieved from login and password.
[2023-12-01T15:38:14.083+0000] {s3_to_redshift.py:192} INFO - Executing COPY command...
[2023-12-01T15:38:14.086+0000] {base.py:73} INFO - Using connection ID 'conn_id_redshift' for task execution.
[2023-12-01T15:40:15.045+0000] {local_task_job_runner.py:294} WARNING - State of this instance has been externally set to restarting. Terminating instance.
[2023-12-01T15:40:15.050+0000] {process_utils.py:131} INFO - Sending Signals.SIGTERM to group 37166. PIDs of all processes in the group: [37166]
[2023-12-01T15:40:15.050+0000] {process_utils.py:86} INFO - Sending the signal Signals.SIGTERM to group 37166
[2023-12-01T15:40:15.050+0000] {taskinstance.py:1632} ERROR - Received SIGTERM. Terminating subprocesses.
[2023-12-01T15:40:15.055+0000] {taskinstance.py:1937} ERROR - Task failed with exception
Traceback (most recent call last):
  File "/home/ubuntu/.local/lib/python3.10/site-packages/airflow/providers/amazon/aws/transfers/s3_to_redshift.py", line 196, in execute
    redshift_hook.run(sql, autocommit=self.autocommit)
  File "/usr/local/lib/python3.10/dist-packages/airflow/providers/common/sql/hooks/sql.py", line 385, in run
    with closing(self.get_conn()) as conn:
  File "/home/ubuntu/.local/lib/python3.10/site-packages/airflow/providers/amazon/aws/hooks/redshift_sql.py", line 176, in get_conn
    return redshift_connector.connect(**conn_kwargs)
  File "/home/ubuntu/.local/lib/python3.10/site-packages/redshift_connector/__init__.py", line 376, in connect
    return Connection(
  File "/home/ubuntu/.local/lib/python3.10/site-packages/redshift_connector/core.py", line 628, in __init__
    self._usock.connect(hostport)
  File "/usr/local/lib/python3.10/dist-packages/airflow/models/taskinstance.py", line 1634, in signal_handler
    raise AirflowException("Task received SIGTERM signal")
airflow.exceptions.AirflowException: Task received SIGTERM signal
[2023-12-01T15:40:15.057+0000] {taskinstance.py:1400} INFO - Marking task as UP_FOR_RETRY. dag_id=zillow_analytics_dag, task_id=tsk_transfer_s3_to_redshift, execution_date=20231201T152937, start_date=20231201T153813, end_date=20231201T154015
[2023-12-01T15:40:15.072+0000] {standard_task_runner.py:104} ERROR - Failed to execute job 80 for task tsk_transfer_s3_to_redshift (Task received SIGTERM signal; 37166)
[2023-12-01T15:40:15.103+0000] {process_utils.py:79} INFO - Process psutil.Process(pid=37166, status='terminated', exitcode=1, started='15:38:13') (37166) terminated with exit code 1
