[2023-12-01T15:36:00.772+0000] {taskinstance.py:1159} INFO - Dependencies all met for dep_context=non-requeueable deps ti=<TaskInstance: zillow_analytics_dag.tsk_transfer_s3_to_redshift manual__2023-12-01T15:23:49.409530+00:00 [queued]>
[2023-12-01T15:36:00.781+0000] {taskinstance.py:1159} INFO - Dependencies all met for dep_context=requeueable deps ti=<TaskInstance: zillow_analytics_dag.tsk_transfer_s3_to_redshift manual__2023-12-01T15:23:49.409530+00:00 [queued]>
[2023-12-01T15:36:00.781+0000] {taskinstance.py:1361} INFO - Starting attempt 5 of 7
[2023-12-01T15:36:00.797+0000] {taskinstance.py:1382} INFO - Executing <Task(S3ToRedshiftOperator): tsk_transfer_s3_to_redshift> on 2023-12-01 15:23:49.409530+00:00
[2023-12-01T15:36:00.801+0000] {standard_task_runner.py:57} INFO - Started process 37115 to run task
[2023-12-01T15:36:00.805+0000] {standard_task_runner.py:84} INFO - Running: ['airflow', 'tasks', 'run', 'zillow_analytics_dag', 'tsk_transfer_s3_to_redshift', 'manual__2023-12-01T15:23:49.409530+00:00', '--job-id', '79', '--raw', '--subdir', '/home/ubuntu/airflow/dags', '--cfg-path', '/tmp/tmpzzqtnfe2']
[2023-12-01T15:36:00.807+0000] {standard_task_runner.py:85} INFO - Job 79: Subtask tsk_transfer_s3_to_redshift
[2023-12-01T15:36:00.843+0000] {task_command.py:416} INFO - Running <TaskInstance: zillow_analytics_dag.tsk_transfer_s3_to_redshift manual__2023-12-01T15:23:49.409530+00:00 [running]> on host ip-172-31-24-255.us-west-2.compute.internal
[2023-12-01T15:36:00.910+0000] {taskinstance.py:1662} INFO - Exporting env vars: AIRFLOW_CTX_DAG_EMAIL='myemail@domain.com' AIRFLOW_CTX_DAG_OWNER='airflow' AIRFLOW_CTX_DAG_ID='zillow_analytics_dag' AIRFLOW_CTX_TASK_ID='tsk_transfer_s3_to_redshift' AIRFLOW_CTX_EXECUTION_DATE='2023-12-01T15:23:49.409530+00:00' AIRFLOW_CTX_TRY_NUMBER='5' AIRFLOW_CTX_DAG_RUN_ID='manual__2023-12-01T15:23:49.409530+00:00'
[2023-12-01T15:36:00.915+0000] {base.py:73} INFO - Using connection ID 'aws_s3_conn' for task execution.
[2023-12-01T15:36:00.917+0000] {base.py:73} INFO - Using connection ID 'aws_s3_conn' for task execution.
[2023-12-01T15:36:00.918+0000] {connection_wrapper.py:378} INFO - AWS Connection (conn_id='aws_s3_conn', conn_type='aws') credentials retrieved from login and password.
[2023-12-01T15:36:00.929+0000] {s3_to_redshift.py:192} INFO - Executing COPY command...
[2023-12-01T15:36:00.932+0000] {base.py:73} INFO - Using connection ID 'conn_id_redshift' for task execution.
[2023-12-01T15:38:11.017+0000] {taskinstance.py:1937} ERROR - Task failed with exception
Traceback (most recent call last):
  File "/home/ubuntu/.local/lib/python3.10/site-packages/redshift_connector/core.py", line 628, in __init__
    self._usock.connect(hostport)
TimeoutError: [Errno 110] Connection timed out

During handling of the above exception, another exception occurred:

Traceback (most recent call last):
  File "/home/ubuntu/.local/lib/python3.10/site-packages/airflow/providers/amazon/aws/transfers/s3_to_redshift.py", line 196, in execute
    redshift_hook.run(sql, autocommit=self.autocommit)
  File "/usr/local/lib/python3.10/dist-packages/airflow/providers/common/sql/hooks/sql.py", line 385, in run
    with closing(self.get_conn()) as conn:
  File "/home/ubuntu/.local/lib/python3.10/site-packages/airflow/providers/amazon/aws/hooks/redshift_sql.py", line 176, in get_conn
    return redshift_connector.connect(**conn_kwargs)
  File "/home/ubuntu/.local/lib/python3.10/site-packages/redshift_connector/__init__.py", line 376, in connect
    return Connection(
  File "/home/ubuntu/.local/lib/python3.10/site-packages/redshift_connector/core.py", line 684, in __init__
    raise OperationalError("connection time out", timeout_error)
redshift_connector.error.OperationalError: ('connection time out', TimeoutError(110, 'Connection timed out'))
[2023-12-01T15:38:11.021+0000] {taskinstance.py:1400} INFO - Marking task as UP_FOR_RETRY. dag_id=zillow_analytics_dag, task_id=tsk_transfer_s3_to_redshift, execution_date=20231201T152349, start_date=20231201T153600, end_date=20231201T153811
[2023-12-01T15:38:11.033+0000] {standard_task_runner.py:104} ERROR - Failed to execute job 79 for task tsk_transfer_s3_to_redshift (('connection time out', TimeoutError(110, 'Connection timed out')); 37115)
[2023-12-01T15:38:11.057+0000] {local_task_job_runner.py:228} INFO - Task exited with return code 1
[2023-12-01T15:38:11.067+0000] {taskinstance.py:2778} INFO - 0 downstream tasks scheduled from follow-on schedule check
